<?xml version="1.0"?>
<robot xmlns:xacro="http://www.ros.org/wiki/xacro" name="aarm">

  <!-- Mesh path property -->
  <xacro:property name="mesh_path" value="file:///home/imbatman/arm_ws/src/aarm/meshes"/>

  <!-- ********************** -->
  <!--        LINKS           -->
  <!-- ********************** -->
  <link name="world" />
  <joint name="base_joint" type="fixed">
      <parent link="world" />
      <child link="base_link" />
    <origin rpy="0 0 3.142" xyz="0.0 0.0 0.0" />
  </joint>

  <link name="base_link">
    <inertial>
      <origin xyz="-1.52896334543362E-18 0.000275869056085517 0.0725700963330659" rpy="0 0 0" />
      <mass value="8.30791197046348" />
      <inertia ixx="0.0224329754109559" ixy="6.6675958021206E-19" ixz="-3.3017759826328E-19" iyy="0.0223382788011866" iyz="0.000114755445160352" izz="0.0102840882798005" />
    </inertial>
    <visual>
      <origin xyz="0 0 0" rpy="0 0 0" />
      <geometry>
        <mesh filename="${mesh_path}/base_link.STL" />
      </geometry>
      <material name="">
        <color rgba="0.647058823529412 0.619607843137255 0.588235294117647 1" />
      </material>
    </visual>
    <collision>
      <origin xyz="0 0 0" rpy="0 0 0" />
      <geometry>
        <mesh filename="${mesh_path}/base_link.STL" />
      </geometry>
    </collision>
  </link>

  <link name="link_1">
    <inertial>
      <origin xyz="6.17970188303797E-08 0.00166209790109974 0.0844306259060318" rpy="0 0 0" />
      <mass value="2.45099397936079" />
      <inertia ixx="0.00731805996091955" ixy="1.46283686815934E-08" ixz="-1.91445176266472E-08" iyy="0.00639245926877078" iyz="-0.000413333474696484" izz="0.00368524719995598" />
    </inertial>
    <visual>
      <origin xyz="0 0 0" rpy="0 0 0" />
      <geometry>
        <mesh filename="${mesh_path}/link_1.STL" />
      </geometry>
      <material name="">
        <color rgba="1 1 1 1" />
      </material>
    </visual>
    <collision>
      <origin xyz="0 0 0" rpy="0 0 0" />
      <geometry>
        <mesh filename="${mesh_path}/link_1.STL" />
      </geometry>
    </collision>
  </link>

  <link name="link_2">
    <inertial>
      <origin xyz="0.00983929891476374 0.162155382481679 0.0529704954898899" rpy="0 0 0" />
      <mass value="5.59063232423513" />
      <inertia ixx="0.0610144279466586" ixy="-0.00688307157299445" ixz="-5.41867245545161E-05" iyy="0.0187392227892053" iyz="-0.0129091667128826" izz="0.0523007533583231" />
    </inertial>
    <visual>
      <origin xyz="0 0 0" rpy="0 0 0" />
      <geometry>
        <mesh filename="${mesh_path}/link_2.STL" />
      </geometry>
      <material name="">
        <color rgba="1 1 1 1" />
      </material>
    </visual>
    <collision>
      <origin xyz="0 0 0" rpy="0 0 0" />
      <geometry>
        <mesh filename="${mesh_path}/link_2.STL" />
      </geometry>
    </collision>
  </link>

  <link name="link_3">
    <inertial>
      <origin xyz="0.0641739037898064 -0.075769852533331 0.0135973711775733" rpy="0 0 0" />
      <mass value="2.74037987212667" />
      <inertia ixx="0.0121436879643637" ixy="0.00373779032527473" ixz="-0.00220875439180711" iyy="0.00950602661953643" iyz="0.00361481025430684" izz="0.0112590444160043" />
    </inertial>
    <visual>
      <origin xyz="0 0 0" rpy="0 0 0" />
      <geometry>
        <mesh filename="${mesh_path}/link_3.STL" />
      </geometry>
      <material name="">
        <color rgba="1 1 1 1" />
      </material>
    </visual>
    <collision>
      <origin xyz="0 0 0" rpy="0 0 0" />
      <geometry>
        <mesh filename="${mesh_path}/link_3.STL" />
      </geometry>
    </collision>
  </link>

  <link name="link_4">
    <inertial>
      <origin xyz="0.000322519637714402 -0.0261611542255079 0.123072076678304" rpy="0 0 0" />
      <mass value="1.28072761958887" />
      <inertia ixx="0.00941242452823936" ixy="1.40408380455933E-05" ixz="1.71732926853513E-05" iyy="0.00905166056382375" iyz="0.000754014239670629" izz="0.00136748274808514" />
    </inertial>
    <visual>
      <origin xyz="0 0 0" rpy="0 0 0" />
      <geometry>
        <mesh filename="${mesh_path}/link_4.STL" />
      </geometry>
      <material name="">
        <color rgba="1 1 1 1" />
      </material>
    </visual>
    <collision>
      <origin xyz="0 0 0" rpy="0 0 0" />
      <geometry>
        <mesh filename="${mesh_path}/link_4.STL" />
      </geometry>
    </collision>
  </link>

  <link name="link_5">
    <inertial>
      <origin xyz="0.0325648110946249 0.0493336474024252 0.005011972938951" rpy="0 0 0" />
      <mass value="1.25851561876916" />
      <inertia ixx="0.00192911911016937" ixy="-0.000458572578654271" ixz="0.000188148532102674" iyy="0.00174494770294687" iyz="0.000270466552389038" izz="0.00266182532707762" />
    </inertial>
    <visual>
      <origin xyz="0 0 0" rpy="0 0 0" />
      <geometry>
        <mesh filename="${mesh_path}/link_5.STL" />
      </geometry>
      <material name="">
        <color rgba="1 1 1 1" />
      </material>
    </visual>
    <collision>
      <origin xyz="0 0 0" rpy="0 0 0" />
      <geometry>
        <mesh filename="${mesh_path}/link_5.STL" />
      </geometry>
    </collision>
  </link>

  <link name="end_effector">
    <inertial>
      <origin xyz="-0.000123789704005067 -5.55111512312578E-17 0.00960614744993958" rpy="0 0 0" />
      <mass value="0.151599184655015" />
      <inertia ixx="5.99195236002354E-05" ixy="3.42555918992898E-21" ixz="1.03938285733457E-08" iyy="6.09842450461302E-05" iyz="-1.18584612615602E-20" izz="0.000111071502738399" />
    </inertial>
    <visual>
      <origin xyz="0 0 0" rpy="0 0 0" />
      <geometry>
        <mesh filename="${mesh_path}/end_effector.STL" />
      </geometry>
      <material name="">
        <color rgba="1 1 1 1" />
      </material>
    </visual>
    <collision>
      <origin xyz="0 0 0" rpy="0 0 0" />
      <geometry>
        <mesh filename="${mesh_path}/end_effector.STL" />
      </geometry>
    </collision>
  </link>

  <link name="gripper_base">
    <inertial>
      <origin xyz="0.000170306906508699 -7.28051977166855E-06 0.0408786595275829" rpy="0 0 0" />
      <mass value="0.186198806753854" />
      <inertia ixx="0.000191310965800587" ixy="4.286766150293E-09" ixz="-7.65376251490543E-09" iyy="0.000285230206902362" iyz="-2.19340978900665E-08" izz="0.000130878019171695" />
    </inertial>
    <visual>
      <origin xyz="0 0 0" rpy="0 0 0" />
      <geometry>
        <mesh filename="${mesh_path}/gripper_base.STL" />
      </geometry>
      <material name="">
        <color rgba="1 1 1 1" />
      </material>
    </visual>
    <collision>
      <origin xyz="0 0 0" rpy="0 0 0" />
      <geometry>
        <mesh filename="${mesh_path}/gripper_base.STL" />
      </geometry>
    </collision>
  </link>

  <link name="right_gripper_arm">
    <inertial>
      <origin xyz="0.019453355895636 0.0428172159788077 -2.22044604925031E-16" rpy="0 0 0" />
      <mass value="0.0132384250325893" />
      <inertia ixx="9.44585364013883E-06" ixy="-2.00207306307496E-06" ixz="-6.40671481607481E-23" iyy="1.51026788494249E-06" iyz="-1.37642853928824E-21" izz="1.07384935534506E-05" />
    </inertial>
    <visual>
      <origin xyz="0 0 0" rpy="0 0 0" />
      <geometry>
        <mesh filename="${mesh_path}/right_gripper_arm.STL" />
      </geometry>
      <material name="">
        <color rgba="1 1 1 1" />
      </material>
    </visual>
    <collision>
      <origin xyz="0 0 0" rpy="0 0 0" />
      <geometry>
        <mesh filename="${mesh_path}/right_gripper_arm.STL" />
      </geometry>
    </collision>
  </link>

  <link name="right_tip">
    <inertial>
      <origin xyz="-0.0159642842335652 0.027065179731159 5.24827020731422E-09" rpy="0 0 0" />
      <mass value="0.0114119203595883" />
      <inertia ixx="2.80718142642526E-06" ixy="6.8259265598596E-07" ixz="-6.32563841132125E-14" iyy="7.55571461075855E-07" iyz="1.67597733357525E-12" izz="2.98432410220829E-06" />
    </inertial>
    <visual>
      <origin xyz="0 0 0" rpy="0 0 0" />
      <geometry>
        <mesh filename="${mesh_path}/right_tip.STL" />
      </geometry>
      <material name="">
        <color rgba="0.250980392156863 0.250980392156863 0.250980392156863 1" />
      </material>
    </visual>
    <collision>
      <origin xyz="0 0 0" rpy="0 0 0" />
      <geometry>
        <mesh filename="${mesh_path}/right_tip.STL" />
      </geometry>
    </collision>
  </link>

  <link name="left_gripper_arm">
    <inertial>
      <origin xyz="-0.0194533558956357 0.0428172159788081 5.55111512312578E-17" rpy="0 0 0" />
      <mass value="0.0132384250325893" />
      <inertia ixx="9.44585364013885E-06" ixy="2.00207306307494E-06" ixz="3.594493254664E-22" iyy="1.51026788494247E-06" iyz="-3.70576914423756E-22" izz="1.07384935534506E-05" />
    </inertial>
    <visual>
      <origin xyz="0 0 0" rpy="0 0 0" />
      <geometry>
        <mesh filename="${mesh_path}/left_gripper_arm.STL" />
      </geometry>
      <material name="">
        <color rgba="1 1 1 1" />
      </material>
    </visual>
    <collision>
      <origin xyz="0 0 0" rpy="0 0 0" />
      <geometry>
        <mesh filename="${mesh_path}/left_gripper_arm.STL" />
      </geometry>
    </collision>
  </link>

  <link name="left_tip">
    <inertial>
      <origin xyz="-0.0350191650818524 0.0270651803819149 -7.04297448139712E-09" rpy="0 0 0" />
      <mass value="0.0114119209644277" />
      <inertia ixx="2.80718158897106E-06" ixy="-6.82592520410452E-07" ixz="-1.78063662591421E-13" iyy="7.55571483225024E-07" iyz="-1.92065755610064E-12" izz="2.98432407230999E-06" />
    </inertial>
    <visual>
      <origin xyz="0 0 0" rpy="0 0 0" />
      <geometry>
        <mesh filename="${mesh_path}/left_tip.STL" />
      </geometry>
      <material name="">
        <color rgba="0.250980392156863 0.250980392156863 0.250980392156863 1" />
      </material>
    </visual>
    <collision>
      <origin xyz="0 0 0" rpy="0 0 0" />
      <geometry>
        <mesh filename="${mesh_path}/left_tip.STL" />
      </geometry>
    </collision>
  </link>

  <link name="gripper_camera">
    <inertial>
      <origin xyz="4.33680868994202E-18 5.55111512312578E-17 -0.00860207027365834" rpy="0 0 0" />
      <mass value="0.00851529124922691" />
      <inertia ixx="5.72032823016266E-07" ixy="1.17320496711722E-22" ixz="-3.03740220337573E-22" iyy="5.72032823016266E-07" iyz="0" izz="8.87510252850143E-07" />
    </inertial>
    <visual>
      <origin xyz="0 0 0" rpy="0 0 0" />
      <geometry>
        <mesh filename="${mesh_path}/gripper_camera.STL" />
      </geometry>
      <material name="">
        <color rgba="0.792156862745098 0.819607843137255 0.933333333333333 1" />
      </material>
    </visual>
    <collision>
      <origin xyz="0 0 0" rpy="0 0 0" />
      <geometry>
        <mesh filename="${mesh_path}/gripper_camera.STL" />
      </geometry>
    </collision>
  </link>

  <!-- ********************** -->
  <!--        JOINTS          -->
  <!-- ********************** -->

  <joint name="joint_1" type="revolute">
    <origin xyz="0 0 0.154" rpy="0 0 0" />
    <parent link="base_link" />
    <child link="link_1" />
    <axis xyz="0 0 -1" />
    <limit lower="0" upper="6.28" effort="11" velocity="2" />
  </joint>

  <joint name="joint_2" type="revolute">
    <origin xyz="0 0.0654000000000001 0.115" rpy="1.5707963267949 0 0" />
    <parent link="link_1" />
    <child link="link_2" />
    <axis xyz="0 0 1" />
    <limit lower="0" upper="2.059" effort="11" velocity="2" />
  </joint>

  <joint name="joint_3" type="revolute">
    <origin xyz="0.0533100000000001 0.284550000000001 0" rpy="0 0 0" />
    <parent link="link_2" />
    <child link="link_3" />
    <axis xyz="0 0 1" />
    <limit lower="0" upper="3.8" effort="11" velocity="2" />
  </joint>

  <joint name="joint_4" type="revolute">
    <origin xyz="0.0844000000000011 -0.171270000000003 0.0570000000000001" rpy="1.5707963267949 0 0" />
    <parent link="link_3" />
    <child link="link_4" />
    <axis xyz="0 0 -1" />
    <limit lower="0" upper="6.28" effort="11" velocity="2" />
  </joint>

  <joint name="joint_5" type="revolute">
    <origin xyz="0 0.0134900000000003 0.200000000000002" rpy="-1.5707963267949 0 0" />
    <parent link="link_4" />
    <child link="link_5" />
    <axis xyz="0 0 -1" />
    <limit lower="-0.83" upper="2.9" effort="11" velocity="2" />
  </joint>

  <joint name="end_effector_joint" type="revolute">
    <origin xyz="0.0908072322719006 0.0449631389820272 0" rpy="0.401425727958696 1.5707963267949 0" />
    <parent link="link_5" />
    <child link="end_effector" />
    <axis xyz="0 0 -1" />
    <limit lower="0" upper="6.28" effort="11" velocity="2" />
  </joint>

  <joint name="gripper_base_joint" type="fixed">
    <origin xyz="-0.00017284601832935 0 0.0203200000000001" rpy="0 0 0" />
    <parent link="end_effector" />
    <child link="gripper_base" />
    <axis xyz="0 0 0" />
  </joint>
<joint name="right_gripper_arm_joint" type="revolute">
  <origin xyz="-0.016452 0 0.0457" rpy="1.5708 0 3.1416" />
  <parent link="gripper_base" />
  <child link="right_gripper_arm" />
  <axis xyz="0 0 -1" />
  <limit lower="0.0" upper="0.785398" effort="10" velocity="1.0" />
  <dynamics damping="0.1" friction="0.1" />
</joint>

<joint name="left_gripper_arm_joint" type="revolute">
  <origin xyz="0.016798 0 0.0457" rpy="1.5708 0 3.1416" />
  <parent link="gripper_base" />
  <child link="left_gripper_arm" />
  <axis xyz="0 0 1" /> <!-- Reversed axis -->
  <limit lower="0" upper="0.785398" effort="10" velocity="1.0" />
  <mimic joint="right_gripper_arm_joint" multiplier="1" offset="0" />
  <dynamics damping="0.1" friction="0.1" />
</joint>
    
  <joint name="right_tip_joint" type="fixed">
    <origin xyz="0.00886672478866557 0.0770611122063379 0" rpy="0 0 0" />
    <parent link="right_gripper_arm" />
    <child link="right_tip" />
    <axis xyz="0 0 0" />
  </joint>

  <joint name="left_tip_joint" type="fixed">
    <origin xyz="0.042117 0.077061 0" rpy="0 0 0" />
    <parent link="left_gripper_arm" />
    <child link="left_tip" />
    <axis xyz="0 0 0" />
  </joint>

  <joint name="gripper_camera_joint" type="fixed">
    <origin xyz="0.00017285 0.032852 0.05937" rpy="0 0 3.1416" />
    <parent link="gripper_base" />
    <child link="gripper_camera" />
    <axis xyz="0 0 0" />
  </joint>

</robot>